Workbook

Sheet Tables_Tarifs
A1: TABLES DE TARIFICATION
A2: AUTO – Puissance (CV) | D2: AUTO – Âge conducteur | G2: AUTO/MOTO – Kilométrage
A3: CV Fiscaux | B3: Coeff. Puissance | D3: Âge (ans) | E3: Coeff. Âge | G3: Km/an (max) | H3: Coeff. Km
A4: 3 | B4: 0.9 | D4: 18 | E4: 1.8 | G4: < 8 000 | H4: 0.85
A5: 4 | B5: 1 | D5: 21 | E5: 1.5 | G5: 8 001–12 000 | H5: 0.95
A6: 5 | B6: 1.1 | D6: 25 | E6: 1.1 | G6: 12 001–15 000 | H6: 1
A7: 6 | B7: 1.2 | D7: 30 | E7: 1 | G7: 15 001–20 000 | H7: 1.1
A8: 7 | B8: 1.35 | D8: 40 | E8: 1 | G8: 20 001–25 000 | H8: 1.2
A9: 8 | B9: 1.5 | D9: 55 | E9: 1.05 | G9: > 25 000 | H9: 1.35
A10: 9 | B10: 1.65 | D10: 65 | E10: 1.15
A11: 10 | B11: 1.8 | D11: 75 | E11: 1.35
A12: 11 | B12: 2
A13: 12 | B13: 2.2
A15: MOTO – Cylindrée | D15: HAB – Superficie (m²) | G15: HAB – Valeur mobilier
A16: Cylindrée (cc) | B16: Coeff. | D16: Surface (m²) | E16: Prime base € | G16: Valeur (€) | H16: Coeff.
A17: 50 | B17: 0.7 | D17: ≤ 30 | E17: 80 | G17: < 20 000 | H17: 0.9
A18: 125 | B18: 0.85 | D18: 31–50 | E18: 110 | G18: 20–30 000 | H18: 1
A19: 250 | B19: 1 | D19: 51–70 | E19: 140 | G19: 30–50 000 | H19: 1.15
A20: 500 | B20: 1.25 | D20: 71–90 | E20: 170 | G20: 50–70 000 | H20: 1.3
A21: 750 | B21: 1.5 | D21: 91–110 | E21: 200 | G21: 70–100 000 | H21: 1.5
A22: 1000 | B22: 1.75 | D22: 111–130 | E22: 235 | G22: > 100 000 | H22: 1.75
A23: > 1000 | B23: 2 | D23: 131–150 | E23: 270
D24: > 150 | E24: 320

Sheet Devis_Auto
A1: 🚗 SIMULATEUR DEVIS – ASSURANCE AUTO
A2: 1. INFORMATIONS CONDUCTEUR
A3: Nom / Prénom du client
A4: Âge du conducteur (ans) | C4: 25
A5: Ancienneté du permis (ans) | C5: 3
A6: CRM actuel (ex. 1.00) | C6: 1
A7: Sinistres responsables (N-1) | C7: 0
A9: 2. VÉHICULE
A10: Marque / Modèle
A11: Puissance fiscale (CV) | C11: 7
A12: Âge du véhicule (ans) | C12: 3
A13: Usage du véhicule | C13: Privé
A14: Kilométrage annuel estimé | C14: 12 001–15 000
A15: Stationnement | C15: Garage privé
A16: Zone géographique | C16: Urbaine
A18: 3. GARANTIES & OPTIONS
A19: Formule principale | C19: Tiers simple
A20: Vol & Incendie | C20: NON
A21: Bris de glace | C21: OUI
A22: Assistance 0 km | C22: OUI
A23: Protection juridique | C23: NON
A24: Multi-contrat (Habitation) | C24: NON
A26: 4. CALCUL DE LA PRIME (automatique)
A27: Coeff. jeune conducteur | C27: =IF(C5<1,2,IF(C5<2,1.5,IF(C5<3,1.25,1))) -> 1
A28: Nouveau CRM | C28: =MIN(3.5,MAX(0.5,IF(C7=0,C6*0.95,C6*1.25^C7))) -> 0.95
A29: Coeff. puissance (CV) | C29: =IFERROR(VLOOKUP(C11,Tables_Tarifs!$A$4:$B$13,2,TRUE()),1) -> 1.35
A30: Coeff. usage | C30: =IF(C13="Professionnel",1.2,IF(C13="Tous déplacements",1.15,IF(C13="Domicile-Travail",1.05,1))) -> 1
A31: Coeff. kilométrage | C31: =IFERROR(VLOOKUP(C14,Tables_Tarifs!$G$4:$H$9,2,FALSE()),1) -> 1
A32: Coeff. zone géographique | C32: =IF(C16="Urbaine",1.15,IF(C16="Péri-urbaine",1.05,1)) -> 1.15
A33: Coeff. formule principale | C33: =IF(C19="Tous risques",1.5,IF(C19="Tiers étendu",1.2,1)) -> 1
A34: Majoration vol/incendie | C34: =IF(C20="OUI",30,0) -> 0
A35: Majoration bris de glace | C35: =IF(C21="OUI",20,0) -> 20
A36: Majoration assistance | C36: =IF(C22="OUI",15,0) -> 15
A37: Majoration protection jur. | C37: =IF(C23="OUI",25,0) -> 0
A38: Remise multi-contrat | C38: =IF(C24="OUI",0.95,1) -> 1
A39: Prime de référence RC (€) | C39: 200
A41: ✅ PRIME ANNUELLE TOTALE (€) | C41: =ROUND((C39*C27*C28*C29*C30*C31*C32*C33+C34+C35+C36+C37)*C38,2) -> 329.98
A42: ↳ Prime mensuelle (÷12) | C42: =ROUND(C41/12,2) -> 27.5
A43: Mois de couverture (prorata) | C43: 12
A44: ↳ Prime prorata (€) | C44: =ROUND(C41*C43/12,2) -> 329.98

Sheet Devis_Moto
A1: 🏍️ SIMULATEUR DEVIS – ASSURANCE MOTO
A2: 1. INFORMATIONS PILOTE
A3: Nom / Prénom
A4: Âge du pilote (ans) | C4: 28
A5: Ancienneté permis (ans) | C5: 4
A6: CRM actuel | C6: 1
A7: Sinistres responsables | C7: 0
A9: 2. MOTO
A10: Marque / Modèle
A11: Cylindrée (cc) | C11: 500
A12: Type de moto | C12: Roadster
A13: Âge de la moto (ans) | C13: 2
A14: Usage | C14: Loisir
A15: Stationnement | C15: Box fermé
A16: Zone géographique | C16: Péri-urbaine
A17: Antivol homologué SRA | C17: OUI
A18: Traceur GPS | C18: NON
A19: Kilométrage annuel | C19: 12 001–15 000
A21: 3. GARANTIES
A22: Formule | C22: Intermédiaire
A23: Vol | C23: OUI
A24: Bris de glace | C24: OUI
A25: Assistance | C25: OUI
A26: Multi-contrat (Auto/Hab) | C26: NON
A28: 4. CALCUL DE LA PRIME (automatique)
A29: Prime de référence RC (€) | C29: 150
A30: Coeff. jeune permis | C30: =IF(C5<1,2,IF(C5<2,1.5,IF(C5<3,1.25,1))) -> 1
A31: Nouveau CRM | C31: =MIN(3.5,MAX(0.5,IF(C7=0,C6*0.95,C6*1.25^C7))) -> 0.95
A32: Coeff. cylindrée | C32: =IFERROR(VLOOKUP(C11,Tables_Tarifs!$A$17:$B$23,2,TRUE()),1) -> 1
A33: Coeff. type moto | C33: =IF(C12="Sportive",1.3,IF(C12="Scooter",0.9,1)) -> 1
A34: Coeff. usage | C34: =IF(C14="Livraison",1.4,IF(C14="Professionnel",1.2,1)) -> 1
A35: Coeff. stationnement | C35: =IF(C15="Rue",1.35,IF(C15="Parking couvert",1.15,IF(C15="Garage privé",0.95,0.9))) -> 0.9
A36: Coeff. zone | C36: =IF(C16="Urbaine",1.2,IF(C16="Péri-urbaine",1.08,1)) -> 1.08
A37: Réduction antivol SRA | C37: =IF(C17="OUI",0.9,1) -> 0.9
A38: Réduction traceur GPS | C38: =IF(C18="OUI",0.95,1) -> 1
A39: Coeff. kilométrage | C39: =IFERROR(VLOOKUP(C19,Tables_Tarifs!$G$4:$H$9,2,FALSE()),1) -> 1
A40: Coeff. formule | C40: =IF(C22="Tous risques",1.5,IF(C22="Intermédiaire",1.2,1)) -> 1.2
A41: Majoration vol | C41: =IF(C23="OUI",25,0) -> 25
A42: Majoration bris de glace | C42: =IF(C24="OUI",15,0) -> 15
A43: Majoration assistance | C43: =IF(C25="OUI",12,0) -> 12
...

Sheet Devis_Habitation
A1: 🏠 SIMULATEUR DEVIS – ASSURANCE HABITATION
A2: 1. INFORMATIONS CLIENT
A3: Nom / Prénom
A4: Nombre d'occupants | C4: 2
A6: 2. LOGEMENT
A7: Type de logement | C7: Appartement
A8: Statut | C8: Locataire
A9: Usage | C9: Résidence principale
A10: Surface habitable (m²) | C10: 65
A11: Nombre de pièces | C11: 3
A12: Année de construction | C12: 1990
A13: Étage(s) | C13: 3
A14: Zone géographique | C14: Urbaine
A15: Zone inondable | C15: NON
A17: 3. SÉCURITÉ & MOBILIER
A18: Valeur mobilier (€) | C18: 40000
A19: Franchise choisie (€) | C19: 300
A20: Alarme homologuée | C20: OUI
A21: Porte blindée | C21: NON
A22: Détecteur incendie/fumée | C22: OUI
A23: Multi-contrat (Auto/Moto) | C23: NON
A25: 4. GARANTIES
A26: Formule | C26: Multirisque habitation
A27: Dommages électriques | C27: OUI
A28: Protection juridique | C28: NON
A29: Objets de valeur (+25k€) | C29: NON
A31: 5. CALCUL DE LA PRIME (automatique)
A32: Prime de base selon surface | C32: =IFERROR(VLOOKUP(C10,Tables_Tarifs!$D$17:$E$24,2,TRUE()),110) -> 110
A33: Coeff. type logement | C33: =IF(C7="Maison",1.25,1) -> 1
A34: Coeff. statut | C34: =IF(C8="Propriétaire non-occupant",0.85,IF(C8="Propriétaire occupant",1.1,1)) -> 1
A35: Coeff. usage | C35: =IF(C9="Résidence secondaire",1.2,IF(C9="Mise en location",1.15,1)) -> 1
A36: Coeff. valeur mobilier | C36: =IFERROR(VLOOKUP(C18,Tables_Tarifs!$G$17:$H$22,2,TRUE()),1) -> 1
A37: Coeff. zone géographique | C37: =IF(C14="Urbaine",1.15,IF(C14="Péri-urbaine",1.05,1)) -> 1.15
A38: Coeff. zone inondable | C38: =IF(C15="OUI",1.25,1) -> 1
A39: Réduction alarme | C39: =IF(C20="OUI",0.92,1) -> 0.92
A40: Réduction porte blindée | C40: =IF(C21="OUI",0.96,1) -> 1
A41: Coeff. formule | C41: =IF(C26="Tous risques",1.4,IF(C26="Multirisque habitation",1.15,1)) -> 1.15
A42: Majoration dommages élec. | C42: =IF(C27="OUI",25,0) -> 25
A43: Majoration protection jur. | C43: =IF(C28="OUI",30,0) -> 0
A44: Majoration objets valeur | C44: =IF(C29="OUI",50,0) -> 0
...

Sheet Synthèse_Comparaison
A1: 📊 SYNTHÈSE ET COMPARAISON DES DEVIS
A3: Produit | B3: Client | C3: Formule | D3: Prime annuelle (€) | E3: Prime mensuelle (€) | F3: CRM appliqué | G3: Remarques
A4: 🚗 Auto | B4: =Devis_Auto!C3 -> 0 | C4: =Devis_Auto!C19 -> Tiers simple | D4: =Devis_Auto!C41 -> 329.98 | E4: =Devis_Auto!C42 -> 27.5 | F4: =Devis_Auto!C28 -> 0.95
A5: 🏍️ Moto | B5: =Devis_Moto!C3 -> 0 | C5: =Devis_Moto!C22 -> Intermédiaire | D5: =Devis_Moto!C46 -> 201.59 | E5: =Devis_Moto!C47 -> 16.8 | F5: =Devis_Moto!C31 -> 0.95
A6: 🏠 Hab. | B6: =Devis_Habitation!C3 -> 0 | C6: =Devis_Habitation!C26 -> Multirisque habitation | D6: =Devis_Habitation!C48 -> 150.9 | E6: =Devis_Habitation!C49 -> 12.58 | F6: N/A
A7: TOTAL TOUS CONTRATS | D7: =SUM(D4:D6) -> 682.47 | E7: =SUM(E4:E6) -> 56.88
A9: 💡 Remise multi-contrat active sur chaque feuille si 'OUI' est sélectionné dans le champ Multi-contrat.

Sheet Guide_Utilisation
A1: 📖 GUIDE D'UTILISATION – CLASSEUR DEVIS ASSURANCES
A2: STRUCTURE DU CLASSEUR
A3: • Feuille "Devis_Auto" → Saisie et calcul automatique pour l'assurance auto
A4: • Feuille "Devis_Moto" → Saisie et calcul automatique pour l'assurance moto
A5: • Feuille "Devis_Habitation" → Saisie et calcul automatique pour l'assurance habitation
A6: • Feuille "Synthèse_Comparaison" → Vue d'ensemble des 3 produits et total multi-contrat
A7: • Feuille "Tables_Tarifs" → Tables de référence (modifier ici pour adapter au barème)
A9: COMMENT UTILISER CE FICHIER
A10: 1. Ouvrez la feuille du produit concerné (Auto, Moto ou Habitation).
A11: 2. Remplissez les cellules en BLEU (données client). Les listes déroulantes guident les choix.
A12: 3. Les cellules NOIRES se calculent automatiquement — ne pas les modifier.
A13: 4. Consultez la feuille "Synthèse_Comparaison" pour le total multi-contrat.
... A34: Le sexe du conducteur ne peut pas être utilisé comme critère tarifaire (CJUE).
